<?xml version="1.0"?>
<robot name="myfirst">

<material name="white">
<color rgba="1 1 1 1"/>
</material>

<material name="black">
<color rgba="0 0 0 1"/>
</material>

  <link name="base_link">
    <visual>
      <geometry>
        <box size="1 1 1"/>
      </geometry>
      <material name="white"/>
    </visual>
    <collision>
    <geometry>
      <box size="1 1 1"/>
    </geometry>
    </collision>
    <inertial>
    <mass value="10"/>
    <inertia ixx="4.16666" ixy="0" ixz="0" iyy="3.8020" iyz="0" izz="1.3020"/>
    </inertial>
  </link>
  <link name="wh">
<visual>
<material name="black"/>
<origin rpy="1.57075 0 0" xyz="0 0 0"/>
<geometry>
<cylinder length="0.02" radius="0.1"/>
</geometry>
</visual>
<collision>
<origin rpy="1.57075 0 0" xyz="0 0 0"/>
<geometry>
<cylinder length="0.02" radius="0.1"/>
</geometry>
</collision>
<inertial>
  <mass value="1"/>
  <inertia ixx="1.0" ixy="0.0" ixz="0.0" iyy="1.0" iyz="0.0" izz="1.0"/>
</inertial>
  </link>
  <joint name="left_front_wheel_joint" type="continuous">
  <axis rpy="0 0 0" xyz="0 1 0"/>
<parent link="base_link"/>
<child link="wh"/>
<origin xyz="0.5 0.5 -0.5"/>
  </joint>


     <gazebo reference="wh">
         <mu1 value="200.0"/>
         <mu2 value="100.0"/>
         <kp value="10000000.0" />
         <kd value="1.0" />
         <fdr1 value="0 1 0" />
         <material>Gazebo/Grey</material>
      </gazebo>

<transmission name="left_front_wheel_trans">
<type>transmission_interface/SimpleTransmission</type>
<actuator name="left_front_wheel_motor">
<mechanicalReduction>1</mechanicalReduction>
</actuator>
<joint name="left_front_wheel_joint">
<hardwareInterface>VelocityJointInterface</hardwareInterface>
</joint>
</transmission>


  <link name="whr">
<visual>
<material name="black"/>
<origin rpy="1.57075 0 0" xyz="0 0 0"/>
<geometry>
<cylinder length="0.02" radius="0.1"/>
</geometry>
</visual>
<collision>
<origin rpy="1.57075 0 0" xyz="0 0 0"/>
<geometry>
<cylinder length="0.02" radius="0.1"/>
</geometry>
</collision>
<inertial>
  <mass value="1"/>
  <inertia ixx="1.0" ixy="0.0" ixz="0.0" iyy="1.0" iyz="0.0" izz="1.0"/>
</inertial>
  </link>
  <joint name="right_front_wheel_joint" type="continuous">
  <axis rpy="0 0 0" xyz="0 1 0"/>
<parent link="base_link"/>
<child link="whr"/>
<origin xyz="0.5 -0.5 -0.5"/>
  </joint>


  <gazebo reference="whr">
    <mu1 value="200.0"/>
    <mu2 value="100.0"/>
    <kp value="10000000.0" />
    <kd value="1.0" />
    <fdr1 value="0 1 0" />
      <material>Gazebo/Grey</material>
   </gazebo>


  <transmission name="right_front_wheel_trans">
  <type>transmission_interface/SimpleTransmission</type>
  <actuator name="rightt_front_wheel_motor">
  <mechanicalReduction>1</mechanicalReduction>
  </actuator>
  <joint name="right_front_wheel_joint">
  <hardwareInterface>VelocityJointInterface</hardwareInterface>
  </joint>
  </transmission>


  <link name="whbr">
<visual>
<material name="black"/>
<origin rpy="1.57075 0 0" xyz="0 0 0"/>
<geometry>
<cylinder length="0.02" radius="0.1"/>
</geometry>
</visual>
<collision>
<origin rpy="1.57075 0 0" xyz="0 0 0"/>
<geometry>
<cylinder length="0.02" radius="0.1"/>
</geometry>
</collision>
<inertial>
  <mass value="1"/>
  <inertia ixx="1.0" ixy="0.0" ixz="0.0" iyy="1.0" iyz="0.0" izz="1.0"/>
</inertial>
  </link>
  <joint name="right_back_wheel_joint" type="continuous">
  <axis rpy="0 0 0" xyz="0 1 0"/>
<parent link="base_link"/>
<child link="whbr"/>
<origin xyz="-0.5 -0.5 -0.5"/>
  </joint>


  <gazebo reference="whbr">
    <mu1 value="200.0"/>
    <mu2 value="100.0"/>
    <kp value="10000000.0" />
    <kd value="1.0" />
    <fdr1 value="0 1 0" />
      <material>Gazebo/Grey</material>
   </gazebo>

  <transmission name="right_back_wheel_trans">
  <type>transmission_interface/SimpleTransmission</type>
  <actuator name="right_back_wheel_motor">
  <mechanicalReduction>1</mechanicalReduction>
  </actuator>
  <joint name="right_back_wheel_joint">
  <hardwareInterface>VelocityJointInterface</hardwareInterface>
  </joint>
  </transmission>



  <link name="whbl">
<visual>
<material name="black"/>
<origin rpy="1.57075 0 0" xyz="0 0 0"/>
<geometry>
<cylinder length="0.02" radius="0.1"/>
</geometry>
</visual>
<collision>
<origin rpy="1.57075 0 0" xyz="0 0 0"/>
<geometry>
<cylinder length="0.02" radius="0.1"/>
</geometry>
</collision>
<inertial>
  <mass value="1"/>
  <inertia ixx="1.0" ixy="0.0" ixz="0.0" iyy="1.0" iyz="0.0" izz="1.0"/>
</inertial>
  </link>
  <joint name="left_back_wheel_joint" type="continuous">
  <axis rpy="0 0 0" xyz="0 1 0"/>
<parent link="base_link"/>
<child link="whbl"/>
<origin xyz="-0.5 0.5 -0.5" rpy="0 0 0"/>
  </joint>


  <gazebo reference="whbl">
    <mu1 value="200.0"/>
    <mu2 value="100.0"/>
    <kp value="10000000.0" />
    <kd value="1.0" />
    <fdr1 value="0 1 0" />
      <material>Gazebo/Grey</material>
   </gazebo>

  <transmission name="left_back_wheel_trans">
  <type>transmission_interface/SimpleTransmission</type>
  <actuator name="left_back_wheel_motor">
  <mechanicalReduction>1</mechanicalReduction>
  </actuator>
  <joint name="left_back_wheel_joint">
  <hardwareInterface>VelocityJointInterface</hardwareInterface>
  </joint>
  </transmission>



  <link name="cam">
  <visual>
    <origin xyz="0.4 0 0.54"/>
  <geometry>
  <cylinder length="0.1" radius="0.1"/>
  </geometry>
  </visual>
  <collision>
    <origin xyz="0.4 0 0.54"/>
  <geometry>
  <cylinder length="0.1" radius="0.1"/>
  </geometry>
  </collision>
  <inertial>
  <mass value="1"/>
  <inertia ixx="0.00333" ixy="0" ixz="0" iyy="0.00333" iyz="0" izz="0.005" />
  </inertial>
  </link>

  <joint name="camjoi" type="fixed">
  <parent link="base_link"/>
  <child link="cam"/>
  </joint>

  <gazebo reference="cam">

    <sensor type="multicamera" name="stereo_camera">
  <update_rate>30.0</update_rate>
  <camera name="left">
    <horizontal_fov>1.3962634</horizontal_fov>
    <image>
      <width>800</width>
      <height>800</height>
      <format>R8G8B8</format>
    </image>
    <clip>
      <near>0.02</near>
      <far>300</far>
    </clip>
    <noise>
      <type>gaussian</type>
      <mean>0.0</mean>
      <stddev>0.007</stddev>
    </noise>
  </camera>
  <camera name="right">
    <pose>0 -0.07 0 0 0 0</pose>
    <horizontal_fov>1.3962634</horizontal_fov>
    <image>
      <width>800</width>
      <height>800</height>
      <format>R8G8B8</format>
    </image>
    <clip>
      <near>0.02</near>
      <far>300</far>
    </clip>
    <noise>
      <type>gaussian</type>
      <mean>0.0</mean>
      <stddev>0.007</stddev>
    </noise>
  </camera>
  <plugin name="stereo_camera_controller" filename="libgazebo_ros_multicamera.so">
    <alwaysOn>true</alwaysOn>
    <updateRate>0.0</updateRate>
    <cameraName>multisense_sl/camera</cameraName>
    <imageTopicName>image_raw</imageTopicName>
    <cameraInfoTopicName>camera_info</cameraInfoTopicName>
    <frameName>cam</frameName>
    <!--<rightFrameName>right_camera_optical_frame</rightFrameName>-->
    <hackBaseline>0.07</hackBaseline>
    <distortionK1>0.0</distortionK1>
    <distortionK2>0.0</distortionK2>
    <distortionK3>0.0</distortionK3>
    <distortionT1>0.0</distortionT1>
    <distortionT2>0.0</distortionT2>
  </plugin>
</sensor>
  </gazebo>

  <joint name="hokuyo_joint" type="fixed">
    <axis xyz="1 0 0" />
    <origin xyz="0.6 0 0" rpy="0 0 0"/>
    <parent link="base_link"/>
    <child link="hokuyo_link"/>
  </joint>

  <!-- Hokuyo Laser -->
  <link name="hokuyo_link">
    <collision>
      <origin xyz="0 0 0" rpy="0 0 0"/>
      <geometry>
    <box size="0.1 0.1 0.1"/>
      </geometry>
    </collision>

    <visual>
      <origin xyz="0 0 0" rpy="0 0 0"/>
      <geometry>
        <mesh filename="package://rrbot_description/meshes/hokuyo.dae"/>
      </geometry>
    </visual>

    <inertial>
      <mass value="1e-5" />
      <origin xyz="0 0 0" rpy="0 0 0"/>
      <inertia ixx="1e-6" ixy="0" ixz="0" iyy="1e-6" iyz="0" izz="1e-6" />
    </inertial>
  </link>


  <!-- hokuyo -->
<gazebo reference="hokuyo_link">
  <sensor type="ray" name="head_hokuyo_sensor">
    <pose>0 0 0 0 0 0</pose>
    <visualize>true</visualize>
    <update_rate>40</update_rate>
    <ray>
      <scan>
        <horizontal>
          <samples>720</samples>
          <resolution>1</resolution>
          <min_angle>-1.570796</min_angle>
          <max_angle>1.570796</max_angle>
        </horizontal>
      </scan>
      <range>
        <min>0.10</min>
        <max>30.0</max>
        <resolution>0.01</resolution>
      </range>
      <noise>
        <type>gaussian</type>
        <!-- Noise parameters based on published spec for Hokuyo laser
             achieving "+-30mm" accuracy at range < 10m.  A mean of 0.0m and
             stddev of 0.01m will put 99.7% of samples within 0.03m of the true
             reading. -->
        <mean>0.0</mean>
        <stddev>0.01</stddev>
      </noise>
    </ray>
    <plugin name="gazebo_ros_head_hokuyo_controller" filename="libgazebo_ros_laser.so">
      <topicName>/rrbot/laser/scan</topicName>
      <frameName>hokuyo_link</frameName>
    </plugin>
  </sensor>
</gazebo>

  <gazebo>
    <plugin name="gazebo_ros_control" filename="libgazebo_ros_control.so">
      <robotNamespace>/</robotNamespace>
      <!-- <wheelSeperation>0.76</wheelSeperation>
      <wheelDiameter>0.2</wheelDiameter> -->
      <legacyModeNS>true</legacyModeNS>
    </plugin>
  </gazebo>

</robot>
