<?xml version="1.0"?>
<robot name="myfirst">

<material name="white">
<color rgba="1 1 1 1"/>
</material>

<material name="black">
<color rgba="0 0 0 1"/>
</material>

  <link name="base_link">
    <visual>
      <geometry>
        <box size="2 0.75 1"/>
      </geometry>
      <material name="white"/>
    </visual>
    <collision>
    <geometry>
      <box size="2 0.75 1"/>
    </geometry>
    </collision>
    <inertial>
    <mass value="10"/>
    <inertia ixx="4.16666" ixy="0" ixz="0" iyy="3.8020" iyz="0" izz="1.3020"/>
    </inertial>
  </link>
  <link name="wh">
<visual>
<material name="black"/>
<origin rpy="1.57075 0 0" xyz="0 0 0"/>
<geometry>
<cylinder length="0.02" radius="0.1"/>
</geometry>
</visual>
<collision>
<origin rpy="1.57075 0 0" xyz="0 0 0"/>
<geometry>
<cylinder length="0.02" radius="0.1"/>
</geometry>
</collision>
<inertial>
  <mass value="1"/>
  <inertia ixx="1.0" ixy="0.0" ixz="0.0" iyy="1.0" iyz="0.0" izz="1.0"/>
</inertial>
  </link>
  <joint name="left_front_wheel_joint" type="continuous">
  <axis rpy="0 0 0" xyz="0 1 0"/>
<parent link="base_link"/>
<child link="wh"/>
<origin xyz="1 0.38 -0.5"/>
  </joint>


     <gazebo reference="wh">
         <mu1 value="200.0"/>
         <mu2 value="100.0"/>
         <kp value="10000000.0" />
         <kd value="1.0" />
         <material>Gazebo/Grey</material>
      </gazebo>

<transmission name="left_front_wheel_trans">
<type>transmission_interface/SimpleTransmission</type>
<actuator name="left_front_wheel_motor">
<mechanicalReduction>1</mechanicalReduction>
</actuator>
<joint name="left_front_wheel_joint">
<hardwareInterface>VelocityJointInterface</hardwareInterface>
</joint>
</transmission>


  <link name="whr">
<visual>
<material name="black"/>
<origin rpy="1.57075 0 0" xyz="0 0 0"/>
<geometry>
<cylinder length="0.02" radius="0.1"/>
</geometry>
</visual>
<collision>
<origin rpy="1.57075 0 0" xyz="0 0 0"/>
<geometry>
<cylinder length="0.02" radius="0.1"/>
</geometry>
</collision>
<inertial>
  <mass value="1"/>
  <inertia ixx="1.0" ixy="0.0" ixz="0.0" iyy="1.0" iyz="0.0" izz="1.0"/>
</inertial>
  </link>
  <joint name="right_front_wheel_joint" type="continuous">
  <axis rpy="0 0 0" xyz="0 1 0"/>
<parent link="base_link"/>
<child link="whr"/>
<origin xyz="1 -0.38 -0.5"/>
  </joint>


  <gazebo reference="whr">
      <mu1 value="200.0"/>
      <mu2 value="100.0"/>
      <kp value="10000000.0" />
      <kd value="1.0" />
      <material>Gazebo/Grey</material>
   </gazebo>


  <transmission name="right_front_wheel_trans">
  <type>transmission_interface/SimpleTransmission</type>
  <actuator name="rightt_front_wheel_motor">
  <mechanicalReduction>1</mechanicalReduction>
  </actuator>
  <joint name="right_front_wheel_joint">
  <hardwareInterface>VelocityJointInterface</hardwareInterface>
  </joint>
  </transmission>


  <link name="whbr">
<visual>
<material name="black"/>
<origin rpy="1.57075 0 0" xyz="0 0 0"/>
<geometry>
<cylinder length="0.02" radius="0.1"/>
</geometry>
</visual>
<collision>
<origin rpy="1.57075 0 0" xyz="0 0 0"/>
<geometry>
<cylinder length="0.02" radius="0.1"/>
</geometry>
</collision>
<inertial>
  <mass value="1"/>
  <inertia ixx="1.0" ixy="0.0" ixz="0.0" iyy="1.0" iyz="0.0" izz="1.0"/>
</inertial>
  </link>
  <joint name="right_back_wheel_joint" type="continuous">
  <axis rpy="0 0 0" xyz="0 1 0"/>
<parent link="base_link"/>
<child link="whbr"/>
<origin xyz="-1 -0.38 -0.5"/>
  </joint>


  <gazebo reference="whbr">
      <mu1 value="200.0"/>
      <mu2 value="100.0"/>
      <kp value="10000000.0" />
      <kd value="1.0" />
      <material>Gazebo/Grey</material>
   </gazebo>

  <transmission name="right_back_wheel_trans">
  <type>transmission_interface/SimpleTransmission</type>
  <actuator name="right_back_wheel_motor">
  <mechanicalReduction>1</mechanicalReduction>
  </actuator>
  <joint name="right_back_wheel_joint">
  <hardwareInterface>VelocityJointInterface</hardwareInterface>
  </joint>
  </transmission>



  <link name="whbl">
<visual>
<material name="black"/>
<origin rpy="1.57075 0 0" xyz="0 0 0"/>
<geometry>
<cylinder length="0.02" radius="0.1"/>
</geometry>
</visual>
<collision>
<origin rpy="1.57075 0 0" xyz="0 0 0"/>
<geometry>
<cylinder length="0.02" radius="0.1"/>
</geometry>
</collision>
<inertial>
  <mass value="1"/>
  <inertia ixx="1.0" ixy="0.0" ixz="0.0" iyy="1.0" iyz="0.0" izz="1.0"/>
</inertial>
  </link>
  <joint name="left_back_wheel_joint" type="continuous">
  <axis rpy="0 0 0" xyz="0 1 0"/>
<parent link="base_link"/>
<child link="whbl"/>
<origin xyz="-1 0.38 -0.5" rpy="0 0 0"/>
  </joint>


  <gazebo reference="whbl">
      <mu1 value="200.0"/>
      <mu2 value="100.0"/>
      <kp value="10000000.0" />
      <kd value="1.0" />
      <material>Gazebo/Grey</material>
   </gazebo>

  <transmission name="left_back_wheel_trans">
  <type>transmission_interface/SimpleTransmission</type>
  <actuator name="left_back_wheel_motor">
  <mechanicalReduction>1</mechanicalReduction>
  </actuator>
  <joint name="left_back_wheel_joint">
  <hardwareInterface>VelocityJointInterface</hardwareInterface>
  </joint>
  </transmission>



  <link name="cam">
  <visual>
    <origin xyz="0.9 0 0.54"/>
  <geometry>
  <cylinder length="0.1" radius="0.1"/>
  </geometry>
  </visual>
  <collision>
    <origin xyz="0.9 0 0.54"/>
  <geometry>
  <cylinder length="0.1" radius="0.1"/>
  </geometry>
  </collision>
  <inertial>
  <mass value="1"/>
  <inertia ixx="0.00333" ixy="0" ixz="0" iyy="0.00333" iyz="0" izz="0.005" />
  </inertial>
  </link>

  <joint name="camjoi" type="fixed">
  <parent link="base_link"/>
  <child link="cam"/>
  </joint>

  <gazebo reference="cam">

    <sensor name="cam_camera" type="depth">
      <update_rate>20</update_rate>
      <camera>
        <horizontal_fov>1.047198</horizontal_fov>
        <image>
          <width>640</width>
          <height>480</height>
          <format>R8G8B8</format>
        </image>

        <clip>
          <near>0.05</near>
          <far>3</far>
        </clip>
      </camera>
      <plugin name="cam_controller" filename="libgazebo_ros_openni_kinect.so">
        <baseline>0.2</baseline>
        <alwaysOn>true</alwaysOn>
        <updateRate>1.0</updateRate>
        <cameraName>camera_ir</cameraName>
           <imageTopicName>/camera/color/image_raw</imageTopicName>
           <cameraInfoTopicName>/camera/color/camera_info</cameraInfoTopicName>
           <depthImageTopicName>/camera/depth/image_raw</depthImageTopicName>
           <depthImageCameraInfoTopicName>/camera/depth/camera_info</depthImageCameraInfoTopicName>
           <pointCloudTopicName>/camera/depth/points</pointCloudTopicName>
        <frameName>cam</frameName>
        <pointCloudCutoff>0.5</pointCloudCutoff>
        <pointCloudCutoffMax>3.0</pointCloudCutoffMax>
        <distortionK1>0.00000001</distortionK1>
        <distortionK2>0.00000001</distortionK2>
        <distortionK3>0.00000001</distortionK3>
        <distortionT1>0.00000001</distortionT1>
        <distortionT2>0.00000001</distortionT2>
        <CxPrime>0</CxPrime>
        <Cx>0</Cx>
        <Cy>0</Cy>
        <focalLength>0</focalLength>
        <hackBaseline>0</hackBaseline>
      </plugin>
    </sensor>
  </gazebo>

  <joint name="hokuyo_joint" type="fixed">
    <axis xyz="1 0 0" />
    <origin xyz="1.1 0 0" rpy="0 0 0"/>
    <parent link="base_link"/>
    <child link="hokuyo_link"/>
  </joint>

  <!-- Hokuyo Laser -->
  <link name="hokuyo_link">
    <collision>
      <origin xyz="0 0 0" rpy="0 0 0"/>
      <geometry>
    <box size="0.1 0.1 0.1"/>
      </geometry>
    </collision>

    <visual>
      <origin xyz="0 0 0" rpy="0 0 0"/>
      <geometry>
        <mesh filename="package://rrbot_description/meshes/hokuyo.dae"/>
      </geometry>
    </visual>

    <inertial>
      <mass value="1e-5" />
      <origin xyz="0 0 0" rpy="0 0 0"/>
      <inertia ixx="1e-6" ixy="0" ixz="0" iyy="1e-6" iyz="0" izz="1e-6" />
    </inertial>
  </link>


  <!-- hokuyo -->
<gazebo reference="hokuyo_link">
  <sensor type="ray" name="head_hokuyo_sensor">
    <pose>0 0 0 0 0 0</pose>
    <visualize>true</visualize>
    <update_rate>40</update_rate>
    <ray>
      <scan>
        <horizontal>
          <samples>720</samples>
          <resolution>1</resolution>
          <min_angle>-1.570796</min_angle>
          <max_angle>1.570796</max_angle>
        </horizontal>
      </scan>
      <range>
        <min>0.10</min>
        <max>30.0</max>
        <resolution>0.01</resolution>
      </range>
      <noise>
        <type>gaussian</type>
        <!-- Noise parameters based on published spec for Hokuyo laser
             achieving "+-30mm" accuracy at range < 10m.  A mean of 0.0m and
             stddev of 0.01m will put 99.7% of samples within 0.03m of the true
             reading. -->
        <mean>0.0</mean>
        <stddev>0.01</stddev>
      </noise>
    </ray>
    <plugin name="gazebo_ros_head_hokuyo_controller" filename="libgazebo_ros_laser.so">
      <topicName>/rrbot/laser/scan</topicName>
      <frameName>hokuyo_link</frameName>
    </plugin>
  </sensor>
</gazebo>

  <gazebo>
    <plugin name="gazebo_ros_control" filename="libgazebo_ros_control.so">
      <robotNamespace>/</robotNamespace>
    </plugin>
  </gazebo>

</robot>
